<?xml version="1.0"?>
<robot name="urdfbot" xmlns:xacro="http://ros.org/wiki/xacro">

  <xacro:property name="scl" value="0.001"/>
  <xacro:property name="PI" value="3.14159265335897931" />

    <link name="base_link">
    <visual>
      <origin xyz="0 0 0" rpy="0 0 ${PI/2}"/>
      <geometry>
        <mesh filename="file://$(find urdf_description)/meshes/obj/base_link.obj" scale="${scl} ${scl} ${scl}"/>
      </geometry>
      <material name="black"/>
    </visual>
    <collision>
      <origin xyz="0 0 0" rpy="0 0 0"/>
      <geometry>
        <mesh filename="file://$(find urdf_description)/meshes/obj/base_link.obj" scale="${scl} ${scl} ${scl}"/>
      </geometry>
    </collision>
    <inertial>
      <mass value="10"/>
      <inertia ixx="0.1" ixy="0.0" ixz="0.0" iyy="0.1" iyz="0.0" izz="0.1"/>
    </inertial>
  </link>

  <link name="motor_left">
    <visual>
      <origin xyz="-0.1 0.05 -0.005" rpy="0 0 0"/>
      <geometry>
        <mesh filename="file://$(find urdf_description)/meshes/obj/motor_and_holder.obj" scale="${scl} ${scl} ${scl}"/>
      </geometry>
      <material name="black"/>
    </visual>
    <collision>
      <origin xyz="-0.1 0.05 -0.005" rpy="0 0 0"/>
      <geometry>
        <mesh filename="file://$(find urdf_description)/meshes/obj/motor_and_holder.obj" scale="${scl} ${scl} ${scl}"/>
      </geometry>
    </collision>
    <inertial>
      <mass value="0.05"/>
      <inertia ixx="7.5e-06" ixy="0.0" ixz="0.0" iyy="7.5e-06" iyz="0.0" izz="7.5e-06"/>
    </inertial>
  </link>

  <joint name="base_link_to_motor_left" type="fixed">
    <origin xyz="0.06 0.1 0.005" rpy="0 0 ${PI/2}"/>
    <parent link="base_link"/>
    <child link="motor_left"/>
  </joint>

  <link name="motor_right">
    <visual>
      <origin xyz="0.1 0.05 -0.005" rpy="0 0 0"/>
      <geometry>
        <mesh filename="file://$(find urdf_description)/meshes/obj/motor_right.obj" scale="${scl} ${scl} ${scl}"/>
      </geometry>
      <material name="black"/>
    </visual>
    <collision>
      <origin xyz="0.1 0.05 -0.005" rpy="0 0 0"/>
      <geometry>
        <mesh filename="file://$(find urdf_description)/meshes/obj/motor_right.obj" scale="${scl} ${scl} ${scl}"/>
      </geometry>
    </collision>
    <inertial>
      <mass value="0.05"/>
      <inertia ixx="7.5e-06" ixy="0.0" ixz="0.0" iyy="7.5e-06" iyz="0.0" izz="7.5e-06"/>
    </inertial>
  </link>

  <joint name="base_link_to_motor_right" type="fixed">
    <!-- <origin xyz="-0.1 -0.05 0.005" rpy="0 0 0"/> -->
    <origin xyz="0.06 -0.1 0.005" rpy="0 0 ${PI/2}"/>
    <parent link="base_link"/>
    <child link="motor_right"/>
  </joint>

  <link name="left_wheel">
    <visual>
      <origin xyz="-0.121 0.04 -0.01925" rpy="0 0 0"/>
      <geometry>
        <mesh filename="file://$(find urdf_description)/meshes/obj/rim_and_tire.obj" scale="${scl} ${scl} ${scl}"/>
      </geometry>
      <material name="orange"/>
    </visual>
    <collision>
      <origin xyz="-0.121 0.04 -0.01925" rpy="0 0 0"/>
      <geometry>
        <mesh filename="file://$(find urdf_description)/meshes/obj/rim_and_tire.obj" scale="${scl} ${scl} ${scl}"/>
      </geometry>
    </collision>
    <inertial>
      <mass value="0.05"/>
      <inertia ixx="1.49e-05" ixy="0.0" ixz="0.0" iyy="1.49e-05" iyz="0.0" izz="2.64e-05"/>
    </inertial>
  </link>

  <joint name="motor_left_to_left_rim" type="continuous">
    <origin xyz="0.021 0.01 0.01425" rpy="0 0 0"/>
    <axis xyz="1 0 0"/>
    <parent link="motor_left"/>
    <child link="left_wheel"/>
  </joint>

  <link name="right_wheel">
    <visual>
      <origin xyz="0.121 0.04 0.01925" rpy="0 ${PI} 0"/>
      <geometry>
        <mesh filename="file://$(find urdf_description)/meshes/obj/rim_and_tire.obj" scale="${scl} ${scl} ${scl}"/>
      </geometry>
      <material name="orange"/>
    </visual>
    <collision>
      <origin xyz="0.121 0.04 0.01925" rpy="0 ${PI} 0"/>
      <geometry>
        <mesh filename="file://$(find urdf_description)/meshes/obj/rim_and_tire.obj" scale="${scl} ${scl} ${scl}"/>
      </geometry>
    </collision>
    <inertial>
      <mass value="0.05"/>
      <inertia ixx="1.49e-05" ixy="0.0" ixz="0.0" iyy="1.49e-05" iyz="0.0" izz="2.64e-05"/>
    </inertial>
  </link>

  <joint name="motor_right_to_right_rim" type="continuous">
    <origin xyz="-0.021 0.01 0.01425" rpy="0 0 0"/>
    <axis xyz="1 0 0"/>
    <parent link="motor_right"/>
    <child link="right_wheel"/>
  </joint>

  <link name="caster_wheel_left">
    <visual>
      <origin xyz="-0.137 0.079 0" rpy="${PI} 0 0"/>
      <geometry>
        <mesh filename="file://$(find urdf_description)/meshes/obj/caster_wheel_1.obj" scale="${scl} ${scl} ${scl}"/>
      </geometry>
      <material name="black"/>
    </visual>
    <collision>
      <origin xyz="-0.137 0.079 0" rpy="${PI} 0 0"/>
      <geometry>
        <mesh filename="file://$(find urdf_description)/meshes/obj/caster_wheel_1.obj" scale="${scl} ${scl} ${scl}"/>
      </geometry>
      <surface>
        <friction>
            <ode>
                <mu>0.001</mu>  <!-- Low static friction -->
                <mu2>0.001</mu2> <!-- Low rolling friction -->
            </ode>
            <bullet>
                <friction>0.001</friction>
            </bullet>
        </friction>
      </surface>
    </collision>
    <inertial>
      <mass value="0.01"/>
      <inertia ixx="6.67e-07" ixy="0.0" ixz="0.0" iyy="6.67e-07" iyz="0.0" izz="6.67e-07"/>
    </inertial>
  </link>

  <joint name="base_link_to_caster_wheel_left" type="fixed">
    <!-- <origin xyz="0.06 0.09 0" rpy="0 0 0"/> -->
    <origin xyz="-0.09 0.06 0" rpy="0 0 0"/>
    <parent link="base_link"/>
    <child link="caster_wheel_left"/>
  </joint>

  <link name="caster_wheel_right">
    <visual>
      <origin xyz="-0.137 0.079 0" rpy="${PI} 0 0"/>
      <geometry>
        <mesh filename="file://$(find urdf_description)/meshes/obj/caster_wheel_1.obj" scale="${scl} ${scl} ${scl}"/>
      </geometry>
      <material name="black"/>
    </visual>
    <collision>
      <origin xyz="-0.137 0.079 0" rpy="${PI} 0 0"/>
      <geometry>
        <mesh filename="file://$(find urdf_description)/meshes/obj/caster_wheel_1.obj" scale="${scl} ${scl} ${scl}"/>
      </geometry>
      <surface>
        <friction>
            <ode>
                <mu>0.0</mu>  <!-- Low static friction -->
                <mu2>0.0</mu2> <!-- Low rolling friction -->
            </ode>
            <bullet>
                <friction>0.0</friction>
            </bullet>
        </friction>
      </surface>
    </collision>
    <inertial>
      <mass value="0.01"/>
      <inertia ixx="6.67e-07" ixy="0.0" ixz="0.0" iyy="6.67e-07" iyz="0.0" izz="6.67e-07"/>
    </inertial>
  </link>

  <joint name="base_link_to_caster_wheel_right" type="fixed">
    <origin xyz="-0.09 -0.06 0" rpy="0 0 0"/>
    <parent link="base_link"/>
    <child link="caster_wheel_right"/>
  </joint>

  <link name="u2d2_link">
    <visual>
      <origin xyz="-0.04 0 -0.005" rpy="0 0 ${PI/2}"/>
      <geometry>
        <mesh filename="file://$(find urdf_description)/meshes/obj/u2d2_and_holder.obj" scale="${scl} ${scl} ${scl}"/>
      </geometry>
      <material name="black"/>
    </visual>
    <collision>
      <origin xyz="-0.04 0 -0.005" rpy="0 0 ${PI/2}"/>
      <geometry>
        <mesh filename="file://$(find urdf_description)/meshes/obj/u2d2_and_holder.obj" scale="${scl} ${scl} ${scl}"/>
      </geometry>
    </collision>
    <!-- <inertial>
      <mass value="0.1"/>
      <inertia ixx="0.1" ixy="0.0" ixz="0.0" iyy="0.1" iyz="0.0" izz="0.1"/>
    </inertial> -->
  </link>

  <joint name="base_link_to_u2d2_link" type="fixed">
    <origin xyz="0.05 0 0.005" rpy="0 0 0"/>
    <parent link="base_link"/>
    <child link="u2d2_link"/>
  </joint>

  <link name="battery_link">
    <visual>
      <origin xyz="0 0 0" rpy="${PI/2} 0 0"/>
      <geometry>
        <mesh filename="file://$(find urdf_description)/meshes/obj/Battery_holder.obj" scale="${scl} ${scl} ${scl}"/>
      </geometry>
      <material name="black"/>
    </visual>
    <collision>
      <origin xyz="0 0 0" rpy="${PI/2} 0 0"/>
      <geometry>
        <mesh filename="file://$(find urdf_description)/meshes/obj/Battery_holder.obj" scale="${scl} ${scl} ${scl}"/>
      </geometry>
    </collision>
    <inertial>
      <mass value="0.15"/>
      <inertia ixx="2.5e-04" ixy="0.0" ixz="0.0" iyy="2.5e-04" iyz="0.0" izz="2.5e-04"/>
    </inertial>
  </link>

  <joint name="base_link_to_battery_link" type="fixed">
    <origin xyz="-0.08 0 0.005" rpy="0 0 0"/>
    <parent link="base_link"/>
    <child link="battery_link"/>
  </joint>

  <link name="spacer_front_right_lvl_0">
    <visual>
      <origin xyz="0.11 0.11 -0.005" rpy="0 0 0"/>
      <geometry>
        <mesh filename="file://$(find urdf_description)/meshes/obj/Distantier_35mm.obj" scale="${scl} ${scl} ${scl}"/>
      </geometry>
      <material name="yellow"/>
    </visual>
    <collision>
      <origin xyz="0.11 0.11 -0.005" rpy="0 0 0"/>
      <geometry>
        <mesh filename="file://$(find urdf_description)/meshes/obj/Distantier_35mm.obj" scale="${scl} ${scl} ${scl}"/>
      </geometry>
    </collision>
    <!-- <inertial>
      <mass value="0.1"/>
      <inertia ixx="0.1" ixy="0.0" ixz="0.0" iyy="0.1" iyz="0.0" izz="0.1"/>
    </inertial> -->
  </link>

  <joint name="base_link_to_spacer_front_right_lvl_0" type="fixed">
    <origin xyz="0.11 -0.11 0.005" rpy="0 0 0"/>
    <parent link="base_link"/>
    <child link="spacer_front_right_lvl_0"/>
  </joint>

  <link name="spacer_middle_right_lvl_0">
    <visual>
      <origin xyz="0.11 0.11 -0.005" rpy="0 0 0"/>
      <geometry>
        <mesh filename="file://$(find urdf_description)/meshes/obj/Distantier_35mm.obj" scale="${scl} ${scl} ${scl}"/>
      </geometry>
      <material name="yellow"/>
    </visual>
    <collision>
      <origin xyz="0.11 0.11 -0.005" rpy="0 0 0"/>
      <geometry>
        <mesh filename="file://$(find urdf_description)/meshes/obj/Distantier_35mm.obj" scale="${scl} ${scl} ${scl}"/>
      </geometry>
    </collision>
    <!-- <inertial>
      <mass value="0.1"/>
      <inertia ixx="0.1" ixy="0.0" ixz="0.0" iyy="0.1" iyz="0.0" izz="0.1"/>
    </inertial> -->
  </link>

  <joint name="base_link_to_spacer_middle_right_lvl_0" type="fixed">
    <origin xyz="0 -0.11 0.005" rpy="0 0 0"/>
    <parent link="base_link"/>
    <child link="spacer_middle_right_lvl_0"/>
  </joint>

  <link name="spacer_back_right_lvl_0">
    <visual>
      <origin xyz="0.11 0.11 -0.005" rpy="0 0 0"/>
      <geometry>
        <mesh filename="file://$(find urdf_description)/meshes/obj/Distantier_35mm.obj" scale="${scl} ${scl} ${scl}"/>
      </geometry>
      <material name="yellow"/>
    </visual>
    <collision>
      <origin xyz="0.11 0.11 -0.005" rpy="0 0 0"/>
      <geometry>
        <mesh filename="file://$(find urdf_description)/meshes/obj/Distantier_35mm.obj" scale="${scl} ${scl} ${scl}"/>
      </geometry>
    </collision>
    <!-- <inertial>
      <mass value="0.1"/>
      <inertia ixx="0.1" ixy="0.0" ixz="0.0" iyy="0.1" iyz="0.0" izz="0.1"/>
    </inertial> -->
  </link>

  <joint name="base_link_to_spacer_back_right_lvl_0" type="fixed">
    <origin xyz="-0.11 -0.11 0.005" rpy="0 0 0"/>
    <parent link="base_link"/>
    <child link="spacer_back_right_lvl_0"/>
  </joint>

  <link name="spacer_front_left_lvl_0">
    <visual>
      <origin xyz="0.11 0.11 -0.005" rpy="0 0 0"/>
      <geometry>
        <mesh filename="file://$(find urdf_description)/meshes/obj/Distantier_35mm.obj" scale="${scl} ${scl} ${scl}"/>
      </geometry>
      <material name="yellow"/>
    </visual>
    <collision>
      <origin xyz="0.11 0.11 -0.005" rpy="0 0 0"/>
      <geometry>
        <mesh filename="file://$(find urdf_description)/meshes/obj/Distantier_35mm.obj" scale="${scl} ${scl} ${scl}"/>
      </geometry>
    </collision>
    <!-- <inertial>
      <mass value="0.1"/>
      <inertia ixx="0.1" ixy="0.0" ixz="0.0" iyy="0.1" iyz="0.0" izz="0.1"/>
    </inertial> -->
  </link>

  <joint name="base_link_to_spacer_front_left_lvl_0" type="fixed">
    <origin xyz="0.11 0.11 0.005" rpy="0 0 0"/>
    <parent link="base_link"/>
    <child link="spacer_front_left_lvl_0"/>
  </joint>

  <link name="spacer_middle_left_lvl_0">
    <visual>
      <origin xyz="0.11 0.11 -0.005" rpy="0 0 0"/>
      <geometry>
        <mesh filename="file://$(find urdf_description)/meshes/obj/Distantier_35mm.obj" scale="${scl} ${scl} ${scl}"/>
      </geometry>
      <material name="yellow"/>
    </visual>
    <collision>
      <origin xyz="0.11 0.11 -0.005" rpy="0 0 0"/>
      <geometry>
        <mesh filename="file://$(find urdf_description)/meshes/obj/Distantier_35mm.obj" scale="${scl} ${scl} ${scl}"/>
      </geometry>
    </collision>
    <!-- <inertial>
      <mass value="0.1"/>
      <inertia ixx="0.1" ixy="0.0" ixz="0.0" iyy="0.1" iyz="0.0" izz="0.1"/>
    </inertial> -->
  </link>

  <joint name="base_link_to_spacer_middle_left_lvl_0" type="fixed">
    <origin xyz="0.0 0.11 0.005" rpy="0 0 0"/>
    <parent link="base_link"/>
    <child link="spacer_middle_left_lvl_0"/>
  </joint>

  <link name="spacer_back_left_lvl_0">
    <visual>
      <origin xyz="0.11 0.11 -0.005" rpy="0 0 0"/>
      <geometry>
        <mesh filename="file://$(find urdf_description)/meshes/obj/Distantier_35mm.obj" scale="${scl} ${scl} ${scl}"/>
      </geometry>
      <material name="yellow"/>
    </visual>
    <collision>
      <origin xyz="0.11 0.11 -0.005" rpy="0 0 0"/>
      <geometry>
        <mesh filename="file://$(find urdf_description)/meshes/obj/Distantier_35mm.obj" scale="${scl} ${scl} ${scl}"/>
      </geometry>
    </collision>
    <!-- <inertial>
      <mass value="0.1"/>
      <inertia ixx="0.1" ixy="0.0" ixz="0.0" iyy="0.1" iyz="0.0" izz="0.1"/>
    </inertial> -->
  </link>

  <joint name="base_link_to_spacer_back_left_lvl_0" type="fixed">
    <origin xyz="-0.11 0.11 0.005" rpy="0 0 0"/>
    <parent link="base_link"/>
    <child link="spacer_back_left_lvl_0"/>
  </joint>
    
  <link name="lvl_1">
    <visual>
      <origin xyz="0 0 -0.04" rpy="0 0 ${PI/2}"/>
      <geometry>
        <mesh filename="file://$(find urdf_description)/meshes/obj/baza_lvl_1.obj" scale="${scl} ${scl} ${scl}"/>
      </geometry>
      <material name="black"/>
    </visual>
    <collision>
      <origin xyz="0 0 -0.04" rpy="0 0 0"/>
      <geometry>
        <mesh filename="file://$(find urdf_description)/meshes/obj/baza_lvl_1.obj" scale="${scl} ${scl} ${scl}"/>
      </geometry>
    </collision>
    <!-- <inertial>
      <mass value="0.1"/>
      <inertia ixx="0.1" ixy="0.0" ixz="0.0" iyy="0.1" iyz="0.0" izz="0.1"/>
    </inertial> -->
  </link>

  <joint name="base_link_to_lvl_1" type="fixed">
    <origin xyz="0 0 0.04" rpy="0 0 0"/>
    <parent link="base_link"/>
    <child link="lvl_1"/>
  </joint>

  <link name="depth_holder_B">
    <visual>
      <origin xyz="-0.08 0 -0.045" rpy="0 0 ${PI/2}"/>
      <geometry>
        <mesh filename="file://$(find urdf_description)/meshes/obj/depth_holder_B.obj" scale="${scl} ${scl} ${scl}"/>
      </geometry>
      <material name="black"/>
    </visual>
    <collision>
      <origin xyz="-0.08 0 -0.045" rpy="0 0 ${PI/2}"/>
      <geometry>
        <mesh filename="file://$(find urdf_description)/meshes/obj/depth_holder_B.obj" scale="${scl} ${scl} ${scl}"/>
      </geometry>
    </collision>
    <!-- <inertial>
      <mass value="0.1"/>
      <inertia ixx="0.1" ixy="0.0" ixz="0.0" iyy="0.1" iyz="0.0" izz="0.1"/>
    </inertial> -->
  </link>

  <joint name="lvl_1_to_depth_holder_B" type="fixed">
    <origin xyz="0.08 0 0.005" rpy="0 0 0"/>
    <parent link="lvl_1"/>
    <child link="depth_holder_B"/>
  </joint>

  <link name="dept_holder_A">
    <visual>
      <origin xyz="-0.08 0 -0.072" rpy="0 0 ${PI/2}"/>
      <geometry>
        <mesh filename="file://$(find urdf_description)/meshes/obj/depth_holder_A.obj" scale="${scl} ${scl} ${scl}"/>
      </geometry>
      <material name="black"/>
    </visual>
    <collision>
      <origin xyz="-0.08 0 -0.072" rpy="0 0 ${PI/2}"/>
      <geometry>
        <mesh filename="file://$(find urdf_description)/meshes/obj/depth_holder_A.obj" scale="${scl} ${scl} ${scl}"/>
      </geometry>
    </collision>
    <!-- <inertial>
      <mass value="0.1"/>
      <inertia ixx="0.1" ixy="0.0" ixz="0.0" iyy="0.1" iyz="0.0" izz="0.1"/>
    </inertial> -->
  </link>

  <joint name="depth_holder_B_to_dept_holder_A" type="fixed">
    <origin xyz="0 0 0.027" rpy="0 0 0"/>
    <!-- <axis xyz="0 1 0"/>
    <limit lower="-0.35" upper="0.35" effort="1000" velocity="0.5"/> -->
    <parent link="depth_holder_B"/>
    <child link="dept_holder_A"/>
  </joint>


  <link name="pi5">
    <visual>
      <origin xyz="0 0 0" rpy="0 0 ${PI/2}"/>
      <geometry>
        <mesh filename="file://$(find urdf_description)/meshes/obj/pi5_and_case.obj" scale="${scl} ${scl} ${scl}"/>
      </geometry>
      <material name="black"/>
    </visual>
    <collision>
      <origin xyz="0 0 0" rpy="0 0 ${PI/2}"/>
      <geometry>
        <mesh filename="file://$(find urdf_description)/meshes/obj/pi5_and_case.obj" scale="${scl} ${scl} ${scl}"/>
      </geometry>
    </collision>
    <!-- <inertial>
      <mass value="0.1"/>
      <inertia ixx="0.1" ixy="0.0" ixz="0.0" iyy="0.1" iyz="0.0" izz="0.1"/>
    </inertial> -->
  </link>

  <joint name="lvl_1_to_pi5" type="fixed">
    <origin xyz="-0.08 0.00 0.01" rpy="0 0 0"/>
    <parent link="lvl_1"/>
    <child link="pi5"/>
  </joint>

  <link name="lidar_holder">
    <visual>
      <origin xyz="0 0 -0.045" rpy="0 0 ${PI/2}"/>
      <geometry>
        <mesh filename="file://$(find urdf_description)/meshes/obj/lidar_holder.obj" scale="${scl} ${scl} ${scl}"/>
      </geometry>
      <material name="black"/>
    </visual>
    <collision>
      <origin xyz="0 0 -0.045" rpy="0 0 ${PI/2}"/>
      <geometry>
        <mesh filename="file://$(find urdf_description)/meshes/obj/lidar_holder.obj" scale="${scl} ${scl} ${scl}"/>
      </geometry>
    </collision>
    <!-- <inertial>
      <mass value="0.1"/>
      <inertia ixx="0.1" ixy="0.0" ixz="0.0" iyy="0.1" iyz="0.0" izz="0.1"/>
    </inertial> -->
  </link>

  <joint name="lvl_1_to_lidar_holder" type="fixed">
    <origin xyz="0 0 0.005" rpy="0 0 0"/>
    <parent link="lvl_1"/>
    <child link="lidar_holder"/>
  </joint>

</robot>